Workbook

Sheet Full Stats
A1: CAMPUS PLACEMENTS - 2025-2026
A2: Stream | F2: Building | G2: Chemical | I2: Computer | N2: Electrical | S2: Mechanical
A3: Sl.no. | B3: Recruitment Team Visited | C3: Type | D3: Category | E3: Date of Visit/Result announce | F3: CV | G3: BT | H3: CH | I3: CS | J3: AIML | K3: CC | L3: IT | M3: DS | N3: BM | O3: EC | P3: EE | Q3: EI | R3: CPS | S3: AE | T3: AU | U3: IP | V3: ME | W3: MT | X3: BE Total | Y3: CTC(Lakhs per annum)
F4: =[1]Summary!$U$4 -> 24 | G4: =[1]Summary!$U$5 -> 53 | H4: =[1]Summary!$U$6 -> 38 | I4: =[1]Summary!$U$7 -> 183 | J4: =[1]Summary!$U$8 -> 123 | K4: =[1]Summary!$U$9 -> 159 | L4: =[1]Summary!$U$10 -> 168 | M4: =[1]Summary!$U$11 -> 109 | N4: =[1]Summary!$U$12 -> 47 | O4: =[1]Summary!$U$13 -> 154 | P4: =[1]Summary!$U$14 -> 78 | Q4: =[1]Summary!$U$15 -> 57 | R4: =[1]Summary!$U$16 -> 55 | S4: =[1]Summary!$U$17 -> 50 | T4: =[1]Summary!$U$18 -> 20 | U4: =[1]Summary!$U$19 -> 19 | V4: =[1]Summary!$U$20 -> 120 | W4: =[1]Summary!$U$21 -> 105 | X4: =SUM(F4:W4) -> 1562
A5: 1 | B5: Deloitte | C5: P | D5: Consulting | E5: 45771 | J5: 1 | X5: =SUM(F5:W5) -> 1 | Y5: 1200000
A6: 2 | B6: Fischer Jordan PPO | C6: P+I | D6: Analytics | E6: 45812 | I6: 2 | X6: =SUM(F6:W6) -> 2 | Y6: 2478000
A7: 3 | B7: Goldman Sachs PPO | C7: P+I | D7: Fintech | E7: 45859 | I7: 2 | K7: 3 | X7: =SUM(F7:W7) -> 5 | Y7: 3000000
A8: 4 | B8: WDC PPO | C8: P+I | D8: Core IT | E8: 45859 | I8: 1 | L8: 1 | O8: 3 | X8: =SUM(F8:W8) -> 5 | Y8: 2181000
A9: 5 | B9: D E Shaw PPO | C9: P+I | D9: Fintech | E9: 45860 | K9: 1 | X9: =SUM(F9:W9) -> 1 | Y9: 3000000
A10: 6 | B10: ITC Foods PPO | C10: P+I | D10: FMCG | E10: 45862 | H10: 1 | Q10: 1 | X10: =SUM(F10:W10) -> 2 | Y10: 1400000
A11: 7 | B11: Saviynt | C11: P+I | D11: Core IT | E11: 45863 | J11: 5 | L11: 2 | X11: =SUM(F11:W11) -> 7 | Y11: 2000000
A12: 8 | B12: Uber PPO | C12: P | D12: Core IT | E12: 45864 | J12: 1 | X12: =SUM(F12:W12) -> 1 | Y12: 4100399
A13: 9 | B13: Volvo | C13: P | D13: Core Engg | E13: 45867 | O13: 2 | V13: 2 | W13: 1 | X13: =SUM(F13:W13) -> 5 | Y13: 750000
A14: 10 | B14: AQR Capital PPO | C14: P | D14: Fintech | E14: 45867 | L14: 2 | X14: =SUM(F14:W14) -> 2 | Y14: 3430600
A15: 11 | B15: GE Healthcare PPO | C15: P+I | D15: Healthcare | E15: 45869 | I15: 1 | K15: 1 | L15: 1 | X15: =SUM(F15:W15) -> 3 | Y15: 1620012
A16: 12 | B16: Boeing PPO | C16: P | D16: Core Engg | E16: 45874 | J16: 2 | L16: 4 | O16: 1 | S16: 1 | X16: =SUM(F16:W16) -> 8 | Y16: 1088038
A17: 13 | B17: JP Morgan PPO | C17: P+I | D17: Fintech | E17: 45874 | I17: 2 | K17: 1 | X17: =SUM(F17:W17) -> 3 | Y17: 1975000
A18: 14 | B18: VISA PPO | C18: P+I | D18: Fintech | E18: 45876 | J18: 1 | X18: =SUM(F18:W18) -> 1 | Y18: 1657000
A19: 15 | B19: Komprise | C19: P+I | D19: Core IT | E19: 45876 | I19: 1 | X19: =SUM(F19:W19) -> 1 | Y19: 2200000
A20: 16 | B20: Oracle | C20: P+I | D20: Core IT | E20: 45877 | I20: 1 | J20: 3 | K20: 1 | L20: 1 | X20: =SUM(F20:W20) -> 6 | Y20: 2136442
A21: 17 | B21: Wellsfargo PPO | C21: P | D21: Fintech | E21: 45880 | J21: 1 | K21: 1 | X21: =SUM(F21:W21) -> 2 | Y21: 2400000
A22: 18 | B22: Meesho | C22: P+I | D22: Core IT | E22: 45880 | I22: 1 | J22: 2 | K22: 2 | M22: 2 | O22: 1 | X22: =SUM(F22:W22) -> 8 | Y22: 2350000
A23: 19 | B23: JP Morgan | C23: P | D23: Fintech | E23: 45882 | K23: 1 | M23: 1 | X23: =SUM(F23:W23) -> 2 | Y23: 1975000
A24: 20 | B24: SAP Labs | C24: P+I | D24: Core IT | E24: 45882 | I24: 2 | J24: 1 | K24: 4 | L24: 8 | M24: 2 | O24: 1 | X24: =SUM(F24:W24) -> 18 | Y24: 2602080
A25: 21 | B25: BNY Mellon PPO | C25: P | D25: Fintech | E25: 45886 | I25: 1 | J25: 1 | L25: 1 | M25: 1 | X25: =SUM(F25:W25) -> 4 | Y25: 2200000
A26: 22 | B26: Microsoft PPO | C26: P | D26: Core IT | E26: 45888 | I26: 3 | K26: 2 | L26: 1 | X26: =SUM(F26:W26) -> 6 | Y26: 5100000
A27: 23 | B27: MUFG | C27: P+I | D27: Fintech | E27: 45888 | I27: 1 | L27: 2 | M27: 1 | X27: =SUM(F27:W27) -> 4 | Y27: 1900000
A28: 24 | B28: Sabre (BA) | C28: P+I | D28: Core IT | E28: 45889 | L28: 1 | M28: 2 | X28: =SUM(F28:W28) -> 3 | Y28: 1329120
A29: 25 | B29: Sabre (SE) | C29: P+I | D29: Coer IT | E29: 45889 | L29: 1 | X29: =SUM(F29:W29) -> 1 | Y29: 1384500
A30: 26 | B30: ITC Foods | C30: P | D30: FMCG | E30: 45889 | Q30: 1 | V30: 1 | X30: =SUM(F30:W30) -> 2 | Y30: 1400000
A31: 27 | B31: Cisco (HW) | C31: P+I | D31: Core Engg | E31: 45891 | O31: 3 | X31: =SUM(F31:W31) -> 3 | Y31: 2473633
A32: 28 | B32: Goldman Sachs PPO | C32: P+I | D32: Fintech | E32: 45891 | P32: 1 | V32: 1 | X32: =SUM(F32:W32) -> 2 | Y32: 875000
A33: 29 | B33: Schneider Electric | C33: P+I | D33: Core Engg | E33: 45891 | K33: 2 | O33: 3 | P33: 1 | W33: 2 | X33: =SUM(F33:W33) -> 8 | Y33: 1200000
A34: 30 | B34: Saviynt | C34: P+I | D34: Core IT | E34: 45892 | I34: 1 | L34: 1 | X34: =SUM(F34:W34) -> 2 | Y34: 2000000
A35: 31 | B35: ABB | C35: P+I | D35: Core Engg | E35: 45893 | K35: 1 | M35: 1 | X35: =SUM(F35:W35) -> 2 | Y35: 1000000
A36: 32 | B36: HPE CPP | C36: P+I | D36: Core IT | E36: 45893 | I36: 4 | X36: =SUM(F36:W36) -> 4 | Y36: 1750000
A37: 33 | B37: Cisco PPO | C37: P+I | D37: Core IT | E37: 45897 | I37: 2 | K37: 1 | L37: 2 | X37: =SUM(F37:W37) -> 5 | Y37: 2473633
A38: 34 | B38: Kenvue PPO | C38: P+I | D38: FMCG | E38: 45898 | I38: 2 | K38: 1 | X38: =SUM(F38:W38) -> 3 | Y38: 1905062
A39: 35 | B39: IBM | C39: P+I | D39: Core IT | E39: 45898 | I39: 1 | J39: 4 | K39: 3 | L39: 5 | M39: 2 | R39: 1 | X39: =SUM(F39:W39) -> 16 | Y39: 1875000
A40: 36 | B40: ZS Associates (BTSA) | C40: P+I | D40: Consulting | E40: 45898 | I40: 3 | K40: 8 | L40: 5 | M40: 1 | O40: 1 | X40: =SUM(F40:W40) -> 18 | Y40: 1415600
...

Sheet Internship
A1: CAMPUS Internship - 2025-26
A2: Stream | G2: Building | H2: Chemical | J2: Computer | O2: Electrical | T2: Mechanical
A3: Sl.no. | B3: Company Name | C3: Duration | D3: Type | E3: Category | F3: Date of Visit | G3: CV | H3: BT | I3: CH | J3: CS | K3: AIML | L3: CC | M3: IT | N3: DS | O3: BM | P3: EC | Q3: EE | R3: IC | S3: CPS | T3: AE | U3: AU | V3: IP | W3: ME | X3: MT | Y3: BE Total | Z3: Stipend
G4: ='Full Stats'!F4 -> 24 | H4: ='Full Stats'!G4 -> 53 | I4: ='Full Stats'!H4 -> 38 | J4: ='Full Stats'!I4 -> 183 | K4: ='Full Stats'!J4 -> 123 | L4: ='Full Stats'!K4 -> 159 | M4: ='Full Stats'!L4 -> 168 | N4: ='Full Stats'!M4 -> 109 | ... R4: ='Full Stats'!Q4 -> 57 | T4: ='Full Stats'!S4 -> 50 | U4: ='Full Stats'!T4 -> 20 | V4: ='Full Stats'!U4 -> 19 | W4: ='Full Stats'!V4 -> 120 | X4: ='Full Stats'!W4 -> 105 | Y4: =SUM(G4:X4) -> 1507
A5: 1 | B5: Intel | C5: July-Dec | D5: I | E5: Core Engg | F5: 45686 | P5: 10 | Y5: =SUM(G5:X5) -> 10 | Z5: 45000
A6: 2 | B6: ARM | C6: July-Dec | D6: I | E6: Core Engg | F6: 45687 | J6: 1 | M6: 1 | Y6: =SUM(G6:X6) -> 2 | Z6: 45000
A7: 3 | B7: Infineon | C7: July-May | D7: I | E7: Core Engg | F7: 45692 | J7: 1 | P7: 1 | Q7: 1 | Y7: =SUM(G7:X7) -> 3 | Z7: 39000
A8: 4 | B8: Schlumberger (SLB) | C8: July-Dec | D8: I | E8: Core Engg | F8: 45715 | N8: 5 | P8: 1 | Y8: =SUM(G8:X8) -> 6 | Z8: 30000
A9: 5 | B9: Commscope | C9: July-May | D9: I | E9: Core IT | F9: 45748 | Y9: =SUM(G9:X9) -> 0
A10: 6 | B10: NetApp | C10: July-May | D10: I | E10: Core Engg | F10: 45748 | K10: 2 | M10: 2 | Y10: =SUM(G10:X10) -> 4 | Z10: 50000
A11: 7 | B11: e6Data | C11: July-June | D11: I | E11: Core IT | F11: 45748 | K11: 1 | Y11: =SUM(G11:X11) -> 1 | Z11: 40000
A12: 8 | B12: Philips | C12: July-June | D12: I | E12: Core IT | F12: 45764 | J12: 2 | L12: 1 | N12: 3 | S12: 1 | Y12: =SUM(G12:X12) -> 7 | Z12: 45000
A13: 9 | B13: Amazon Tech | C13: July-Dec | D13: I | E13: Core Engg | F13: 45765 | J13: 3 | K13: 2 | M13: 2 | N13: 1 | Y13: =SUM(G13:X13) -> 8 | Z13: 70000
A14: 10 | B14: Amazon Non Tech | C14: July-Dec | D14: I | E14: Core Engg | F14: 45765 | J14: 1 | N14: 10 | X14: 2 | Y14: =SUM(G14:X14) -> 13 | Z14: 70000
A15: 11 | B15: Harness | C15: July-June | D15: I | E15: Core IT | F15: 45765 | K15: 3 | M15: 1 | N15: 1 | Y15: =SUM(G15:X15) -> 5 | Z15: 70000
A16: 12 | B16: Super Agi | C16: July-Dec | D16: I | E16: Core IT | F16: 45770 | J16: 1 | M16: 1 | Y16: =SUM(G16:X16) -> 2 | Z16: 40000
A17: 13 | B17: Indus Insights | C17: July-Dec | D17: I | E17: Core IT | F17: 45771 | K17: 2 | N17: 2 | P17: 1 | W17: 1 | Y17: =SUM(G17:X17) -> 6 | Z17: 100000
A18: 14 | B18: DBS Technology | C18: July-June | D18: I | E18: Fintech | F18: 45782 | M18: 1 | Y18: =SUM(G18:X18) -> 1 | Z18: 90000
A19: 15 | B19: ST Microelectronics | C19: July-June | D19: I | E19: Core Engg | F19: 45790 | P19: 4 | Q19: 4 | R19: 2 | Y19: =SUM(G19:X19) -> 10 | Z19: 40000
A20: 16 | B20: Barsys | C20: July-Dec | D20: I | E20: Core IT | F20: 45806 | Y20: =SUM(G20:X20) -> 0
A21: 17 | B21: Samsung Electro Mechanics | C21: July-June | D21: I | E21: Core Engg | F21: 45807 | N21: 1 | Y21: =SUM(G21:X21) -> 1 | Z21: 30000
A22: 18 | B22: MSCI | C22: July-Dec | D22: I | E22: FinTech | F22: 45810 | J22: 1 | Y22: =SUM(G22:X22) -> 1 | Z22: 60000
A23: 19 | B23: The Porter | C23: July-Dec | D23: I | E23: Core Engg | F23: 45812 | H23: 1 | I23: 1 | O23: 1 | P23: 1 | Q23: 1 | W23: 2 | Y23: =SUM(G23:X23) -> 7 | Z23: 40000
B24: Fischer Jordan PPO | C24: Jan-June | D24: P+I | E24: Analytics | F24: 45812 | J24: 2 | Y24: =SUM(G24:X24) -> 2 | Z24: 60000
A25: 20 | B25: Equal | C25: July-Dec | D25: I | E25: Core IT | F25: 45819 | Y25: =SUM(G25:X25) -> 0
A26: 21 | B26: Nvidia | C26: July-Dec | D26: I | E26: Core Engg | F26: 45832 | J26: 1 | Y26: =SUM(G26:X26) -> 1 | Z26: 80000
A27: 22 | B27: Twara Robotics | C27: July-July | D27: I | E27: Core Engg | F27: 45846 | W27: 1 | Y27: =SUM(G27:X27) -> 1 | Z27: 25000
A28: 23 | B28: Aecesium | C28: July-Dec | D28: I | E28: Core IT | F28: 45855 | J28: 1 | L28: 1 | Y28: =SUM(G28:X28) -> 2 | Z28: 125000
B29: Goldman Sachs PPO | C29: Jan-June | D29: P+I | E29: Fintech | F29: 45859 | J29: 2 | L29: 3 | Y29: =SUM(G29:X29) -> 5 | Z29: 162000
B30: WDC PPO | C30: Jan-June | D30: P+I | E30: Core IT | F30: 45859 | J30: 1 | M30: 1 | P30: 3 | Y30: =SUM(G30:X30) -> 5 | Z30: 35000
B31: D E Shaw PPO | C31: July-July | D31: P+I | E31: Fintech | F31: 45860 | L31: 1 | Y31: =SUM(G31:X31) -> 1 | Z31: 180000
A32: 24 | B32: Siemens Healthineers | C32: July-July | D32: I | E32: Core Engg | F32: 45860 | O32: 1 | X32: 1 | Y32: =SUM(G32:X32) -> 2 | Z32: 25000
A33: 25 | B33: Resmed | C33: July-June | D33: I | E33: Core Engg | F33: 45861 | O33: 1 | Y33: =SUM(G33:X33) -> 1 | Z33: 45000
A34: 26 | B34: HyperVerge (ML) | C34: Aug-June | D34: I | E34: Core IT | F34: 45862 | K34: 1 | Y34: =SUM(G34:X34) -> 1 | Z34: 45000
B35: HyperVerge (DE) | C35: Aug-June | D35: I | E35: Core IT | F35: 45862 | K35: 1 | Y35: =SUM(G35:X35) -> 1 | Z35: 45000
B36: ITC Foods PPO | C36: Jan-June | D36: P+I | E36: FMCG | F36: 45862 | I36: 1 | R36: 1 | Y36: =SUM(G36:X36) -> 2
B37: Saviynt | C37: Aug-June | D37: P+I | E37: Core IT | F37: 45863 | K37: 5 | M37: 2 | Y37: =SUM(G37:X37) -> 7 | Z37: 70000
B38: GE Healthcare PPO | C38: Jan-June | D38: P+I | E38: Healthcare | F38: 45869 | J38: 1 | L38: 1 | M38: 1 | Y38: =SUM(G38:X38) -> 3 | Z38: 40000
A39: 28 | B39: SAP Labs | C39: Aug-May | D39: I | E39: Core IT | F39: 45870 | L39: 1 | N39: 2 | Y39: =SUM(G39:X39) -> 3 | Z39: 35000
B40: JP Morgan PPO | C40: Jan-June | D40: P+I | E40: Fintech | F40: 45874 | J40: 2 | L40: 1 | Y40: =SUM(G40:X40) -> 3 | Z40: 80000
...

Sheet Students List
A1: Sl.No. | B1: Reg. No. | C1: Name | D1: CGPA | E1: Contact No. | F1: Email id | G1: Branch | H1: Company Name | I1: Offer Type | J1: CTC | K1: Stipend
A2: 1 | B2: 220962356 | C2: Aditya Gosavi | D2: 8.31 | E2: 9623378824 | F2: adityajgosavi@gmail.com | G2: Electrical & Electronics (EE) | H2: Deloitte | I2: P | J2: 1200000
A3: 2 | B3: 220905006 | C3: Aditya Amit Kinjawadekar | D3: 8.93 | E3: 8310309620 | F3: k.aditya2004@gmail.com | G3: Electrical & Electronics (EE) | H3: Fischer Jordan PPO | I3: P+I | J3: 2478000 | K3: 60000
A4: 3 | B4: 220905192 | C4: Sathu Ashrith | D4: 7.11 | E4: 6301434436 | F4: sathuashrith@gmail.com | G4: Computer Science (CS) | H4: Fischer Jordan PPO | I4: P+I | J4: 2478000 | K4: 60000
A5: 4 | B5: 220953516 | C5: Triyan Mukherjee | D5: 8.66 | E5: 9353455845 | F5: triyanmukherjee@gmail.com | G5: Computer & Communication (CC) | H5: Goldman Sachs PPO | I5: P+I | J5: 3000000 | K5: 162000
A6: 5 | B6: 220953202 | C6: Avadhanam Ruthvik | D6: 8.55 | E6: 7674084916 | F6: aruthvik125@gmail.com | G6: Computer & Communication (CC) | H6: Goldman Sachs PPO | I6: P+I | J6: 3000000 | K6: 162000
A7: 6 | B7: 220953230 | C7: Pragya Gupta | D7: 7.93 | E7: 9920959951 | F7: pragyag2575@gmail.com | G7: Computer & Communication (CC) | H7: Goldman Sachs PPO | I7: P+I | J7: 3000000 | K7: 162000
A8: 7 | B8: 220905544 | C8: Ira Lath Gupta | D8: 9.55 | E8: 9619045161 | F8: iralathgupta@gmail.com | G8: Computer Science (CS) | H8: Goldman Sachs PPO | I8: P+I | J8: 3000000 | K8: 162000
A9: 8 | B9: 220905496 | C9: Areen Chakraborty | D9: 9.45 | E9: 8928830710 | F9: areen.c4@gmail.com | G9: Computer Science (CS) | H9: Goldman Sachs PPO | I9: P+I | J9: 3000000 | K9: 162000
A10: 9 | B10: 220905002 | C10: Pratham Shetty | D10: 9.64 | E10: 9945043670 | F10: prathamshetty484@gmail.com | G10: Computer Science (CS) | H10: WDC PPO | I10: P+I | J10: 2181000 | K10: 35000
A11: 10 | B11: 220911672 | C11: Dillon Asher Almeida | D11: 9.04 | E11: 8668633682 | F11: dillonalmeida80@gmail.com | G11: Information Technology (IT) | H11: WDC PPO | I11: P+I | J11: 2181000 | K11: 35000
A12: 11 | B12: 220907278 | C12: Ramya Anand | D12: 8.35 | E12: 8121253429 | F12: ramya29nrj@gmail.com | G12: Electronics & Communication (EC) | H12: WDC PPO | I12: P+I | J12: 2181000 | K12: 35000
A13: 12 | B13: 220907826 | C13: Steve Mathew Augustian | D13: 7.92 | E13: 9740502283 | F13: stevemathew2004@gmail.com | G13: Electronics & Communication (EC) | H13: WDC PPO | I13: P+I | J13: 2181000 | K13: 35000
A14: 13 | B14: 220907670 | C14: Aditya Raj Singh | D14: 8.32 | E14: 9334434232 | F14: adityarajsingh24.12@gmail.com | G14: Electronics & Communication (EC) | H14: WDC PPO | I14: P+I | J14: 2181000 | K14: 35000
A15: 14 | B15: 220953410 | C15: Rohit Sangubotla | D15: 9.2 | E15: 8886926310 | F15: sangubotlarohit@gmail.com | G15: Computer & Communication (CC) | H15: D E Shaw PPO | I15: P+I | J15: 3000000 | K15: 180000
A16: 15 | B16: 220903104 | C16: Siddhika Ajmera | D16: 8.56 | E16: 7877819938 | F16: siddhika.ajmera.1@gmail.com | G16: Chemical (CH) | H16: ITC Foods PPO | I16: P+I | J16: 1400000
A17: 16 | B17: 220932392 | C17: Paarth Goel | D17: 7.5 | E17: 9321793974 | F17: paarthgoelofficial@gmail.com | G17: Electronics & Instrumentation (E&I) | H17: ITC Foods PPO | I17: P+I | J17: 1400000
A18: 17 | B18: 220962314 | C18: Morvin Prajapati | D18: 8.64 | E18: 7259484661 | F18: tactmorvinap259@gmail.com | G18: CSE AIML | H18: Saviynt | I18: P+I | J18: 2000000 | K18: 70000
A19: 18 | B19: 220962018 | C19: Jeffin Joffy P | D19: 8.58 | E19: 8281596331 | F19: jeffinjoffyp123@gmail.com | G19: CSE AIML | H19: Saviynt | I19: P+I | J19: 2000000 | K19: 70000
A20: 19 | B20: 220962384 | C20: Harshita Jangir | D20: 8.49 | E20: 9530071832 | F20: harshita.jangir08@gmail.com | G20: CSE AIML | H20: Saviynt | I20: P+I | J20: 2000000 | K20: 70000
A21: 20 | B21: 220962296 | C21: Aashna Baheti | D21: 7.89 | E21: 9321606234 | F21: aashna.baheti@gmail.com | G21: CSE AIML | H21: Saviynt | I21: P+I | J21: 2000000 | K21: 70000
A22: 21 | B22: 220962412 | C22: Ashwin Bhat | D22: 7.64 | E22: 9049768106 | F22: ashwin.bhat.m@gmail.com | G22: CSE AIML | H22: Saviynt | I22: P+I | J22: 2000000 | K22: 70000
A23: 22 | B23: 220911352 | C23: Srujana Madiraju | D23: 8.26 | E23: 8341209222 | F23: 2004srujana@gmail.com | G23: Information Technology (IT) | H23: Saviynt | I23: P+I | J23: 2000000 | K23: 70000
A24: 23 | B24: 220911470 | C24: Vannela Harshavardhan Reddy | D24: 7.57 | E24: 9390300076 | F24: harshavardhanr0710@gmail.com | G24: Information Technology (IT) | H24: Saviynt | I24: P+I | J24: 2000000 | K24: 70000
A25: 24 | B25: 220962338 | C25: Ambuj Shukla | D25: 8.83 | E25: 7428500775 | F25: ambujshukla2004@gmail.com | G25: CSE AIML | H25: Uber PPO | I25: P | J25: 4100399
A26: 25 | B26: 220907814 | C26: Jay Tewari | D26: 7.13 | E26: 9864406627 | F26: jaytewari21@gmail.com | G26: Electronics & Communication (EC) | H26: Volvo | I26: P | J26: 750000
A27: 26 | B27: 220907280 | C27: Teja Ram | D27: 8.42 | E27: 8073596802 | F27: 4tejavsss@gmail.com | G27: Electronics & Communication (EC) | H27: Volvo | I27: P | J27: 750000
A28: 27 | B28: 220909072 | C28: Amber Bhargava | D28: 7.26 | E28: 9634302113 | F28: amber.bhargava501@gmail.com | G28: Mechanical (ME) | H28: Volvo | I28: P+I | J28: 750000
A29: 28 | B29: 220909048 | C29: Rajneesh Chiplunkar | D29: 8.35 | E29: 8928413716 | F29: rrchiplunkar25@gmail.com | G29: Mechanical (ME) | H29: Volvo | I29: P+I | J29: 750000
A30: 29 | B30: 220929134 | C30: Sai Adithya Pavan Jayanthi | D30: 7.98 | E30: 9100204547 | F30: saiadithya67@gmail.com | G30: Mechatronics (MT) | H30: Volvo | I30: P+I | J30: 750000
A31: 30 | B31: 220911486 | C31: Vaibhavv Maheshwari | D31: 8.93 | E31: 8208467996 | F31: mvaibhavv17@gmail.com | G31: Information Technology (IT) | H31: AQR Capital PPO | I31: P | J31: 3430600
A32: 31 | B32: 220911478 | C32: Ishan Surana | D32: 8.49 | E32: 7977990529 | F32: ishansurana1234@gmail.com | G32: Information Technology (IT) | H32: AQR Capital PPO | I32: P | J32: 3430600
A33: 32 | B33: 220905179 | C33: Sanskriti Labroo | D33: 8.4 | E33: 8971754306 | F33: sanskritilabroo@gmail.com | G33: Computer Science (CS) | H33: GE Healthcare PPO | I33: P+I | J33: 1620012 | K33: 40000
A34: 33 | B34: 220953458 | C34: Rushil Jalal | D34: 7.94 | E34: 9833127837 | F34: rushiljalal@gmail.com | G34: Computer & Communication (CC) | H34: GE Healthcare PPO | I34: P+I | J34: 1620012 | K34: 40000
A35: 34 | B35: 220911038 | C35: Medini S Rao | D35: 8.22 | E35: 9110855168 | F35: medini98765@gmail.com | G35: Information Technology (IT) | H35: GE Healthcare PPO | I35: P+I | J35: 1620012 | K35: 40000
A36: 35 | B36: 220933094 | C36: Abhinav Pradeep Naidu | D36: 8.41 | E36: 9620604875 | F36: abhinavpradeep558@gmail.com | G36: Aeronautical (AE) | H36: Boeing PPO | I36: P | J36: 1088038
A37: 36 | B37: 220907844 | C37: Swetha M R | D37: 8.21 | E37: 6374663716 | F37: swethamageshwaran09@gmail.com | G37: Electronics & Communication (EC) | H37: Boeing PPO | I37: P | J37: 1088038
A38: 37 | B38: 220962013 | C38: Nikhil Nair | D38: 7.8 | E38: 9036237930 | F38: nikhil37464@gmail.com | G38: CSE AIML | H38: Boeing PPO | I38: P | J38: 1088038
A39: 38 | B39: 220962394 | C39: Aaditya Jain | D39: 8.26 | E39: 9311208671 | F39: aaddii22022@gmail.com | G39: CSE AIML | H39: Boeing PPO | I39: P | J39: 1088038
A40: 39 | B40: 220911006 | C40: Shravari | D40: 7.57 | E40: 8296374626 | F40: shravarik4@gmail.com | G40: Information Technology (IT) | H40: Boeing PPO | I40: P | J40: 1088038
...
